Workbook

Sheet Índice
A1: SINISTRALIDADE RODOVIÁRIA A 30 DIAS
A3: QUADROS DE RESULTADOS
A5: Ano 2024
A7: SINISTRALIDADE
A9: ='1.1'!A1 -> Quadro 1.1 Sinistralidade em Portugal por mês
A10: ='1.2'!A1 -> Quadro 1.2 Sinistralidade em Portugal por dia da semana
A11: ='1.3'!A1 -> Quadro 1.3 Sinistralidade em Portugal por período horário
A12: ='1.4'!A1 -> Quadro 1.4 Sinistralidade em Portugal por fatores atmosféricos
A13: ='1.5'!A1 -> Quadro 1.5 Sinistralidade em Portugal por condições de luminosidade
A14: ='1.6'!A1 -> Quadro 1.6 Sinistralidade em Portugal por natureza do acidente
A15: ='1.7'!A1 -> Quadro 1.7 Sinistralidade em Portugal por natureza detalhada do acidente
A16: ='1.8'!A1 -> Quadro 1.8 Sinistralidade em Portugal por localização do acidente
A17: ='1.9'!A1 -> Quadro 1.9 Sinistralidade em Portugal por tipo de via
A18: ='1.10'!A1 -> Quadro 1.10 Sinistralidade em Portugal por distrito e R.A.
A20: VEÍCULOS INTERVENIENTES
A22: ='2.1'!A1 -> Quadro 2.1 Veículos intervenientes em acidentes com vítimas em Portugal por categoria e natureza do acidente
A23: ='2.2'!A1 -> Quadro 2.2 Veículos intervenientes em acidentes com vítimas em Portugal por categoria e idade do veículo
A24: Quadro 2.3 Veículos intervenientes em acidentes com vítimas em Portugal por NUTS I e categoria de veículo
A26: VÍTIMAS
A28: ='3.1'!A1 -> Quadro 3.1 Vítimas em Portugal por categoria de utente
A29: ='3.2'!A1 -> Quadro 3.2 Vítimas em Portugal por categoria de veículo
A30: ='3.3'!A1 -> Quadro 3.3 Vítimas em Portugal por sexo
A31: ='3.4'!A1 -> Quadro 3.4 Vítimas em Portugal por grupo etário
A32: ='3.5'!A1 -> Quadro 3.5 Vítimas mortais em Portugal por milhão de habitantes, segundo o grupo etário
A34: PEÕES
A36: ='4.1'!A1 -> Quadro 4.1 Peões vítimas em Portugal por regiões NUTS I
A37: ='4.2'!A1 -> Quadro 4.2 Evolução peões vítimas em Portugal, 2019 a 2024
A38: ='4.3'!A1 -> Quadro 4.3 Peões vítimas em Portugal por mês
A39: ='4.4'!A1 -> Quadro 4.4 Peões vítimas em Portugal por dia da semana
A40: ='4.5'!A1 -> Quadro 4.5 Peões vítimas em Portugal por período horário
A41: ='4.6'!A1 -> Quadro 4.6 Peões vítimas em Portugal por fatores atmosféricos
A42: ='4.7'!A1 -> Quadro 4.7 Peões vítimas em Portugal segundo a luminosidade
A43: ='4.8'!A1 -> Quadro 4.8 Peões vítimas em Portugal segundo a localização
A44: ='4.9'!A1 -> Quadro 4.9 Peões vítimas em Portugal por tipo de via
A45: ='4.10'!A1 -> Quadro 4.10 Peões vítimas em Portugal por distrito e R.A.
A46: ='4.11'!A1 -> Quadro 4.11 Peões vítimas em Portugal por ação do peão
A47: ='4.12'!A1 -> Quadro 4.12 Peões vítimas em Portugal por sexo
A48: ='4.13'!A1 -> Quadro 4.13 Peões vítimas em Portugal por grupo etário
A50: PASSAGEIROS
A52: ='5.1'!A1 -> Quadro 5.1 Passageiros vítimas em Portugal, por NUTS I
...

Sheet Siglas
A1: SIGLAS E ABREVIATURAS
A3: ACAP | B3: Associação Automóvel de Portugal
A4: ANSR | B4: Autoridade Nacional de Segurança Rodoviária
A5: CE | B5: Comissão Europeia
A6: BEAV | B6: Boletim Estatístico de Acidente de Viação
A7: GNR | B7: Guarda Nacional Republicana
A8: PSP | B8: Polícia de Segurança Pública
A9: PML | B9: Polícia Municipal
A10: SINCRO | B10: Sistema Nacional de Controlo de Velocidade
A11: p.p. | B11: Pontos percentuais
A12: IGR | B12: Índice de gravidade
A13: EUROSTAT | B13: Serviço de Estatística da União Europeia
A14: IMT | B14: Instituto da Mobilidade e dos Transportes
... A23: AcV | B23: Acidente com vítimas

Sheet 1.1
A1: Quadro 1.1 Sinistralidade em Portugal por mês
A3: Mês | B3: AcV | F3: VM | J3: FG | N3: FL
B4: 2019 | C4: 2023 | D4: 2024 | E4: ∆(%) 24/23 | F4: 2019 | G4: 2023 | H4: 2024 | I4: ∆(%) 24/23 | J4: 2019 | K4: 2023 | L4: 2024 | M4: ∆(%) 24/23 | N4: 2019 | O4: 2023 | P4: 2024 | Q4: ∆(%) 24/23
A5: Jan | B5: 2953 | C5: 2780 | D5: 2798 | E5: =D5/C5-1 -> 0.0064748201 | F5: 68 | G5: 57 | H5: 45 | I5: =H5/G5-1 -> -0.21052632 | J5: 155 | K5: 177 | L5: 187 | M5: =L5/K5-1 -> 0.056497175 | N5: 3515 | O5: 3252 | P5: 3245 | Q5: =P5/O5-1 -> -0.0021525215
A6: Fev | B6: 2470 | C6: 2423 | D6: 2720 | E6: =D6/C6-1 -> 0.12257532 | F6: 48 | G6: 46 | H6: 41 | I6: =H6/G6-1 -> -0.10869565 | J6: 140 | K6: 161 | L6: 176 | M6: =L6/K6-1 -> 0.093167702 | N6: 2937 | O6: 2795 | P6: 3199 | Q6: =P6/O6-1 -> 0.14454383
A7: Mar | B7: 2998 | C7: 2800 | D7: 2768 | E7: =D7/C7-1 -> -0.011428571 | F7: 46 | G7: 43 | H7: 43 | I7: =H7/G7-1 -> 0 | J7: 202 | K7: 174 | L7: 172 | M7: =L7/K7-1 -> -0.011494253 | N7: 3603 | O7: 3248 | P7: 3217 | Q7: =P7/O7-1 -> -0.009544335
A8: Abr | B8: 2791 | C8: 2960 | D8: 3057 | E8: =D8/C8-1 -> 0.03277027 | F8: 71 | G8: 67 | H8: 43 | I8: =H8/G8-1 -> -0.35820896 | J8: 175 | K8: 222 | L8: 220 | M8: =L8/K8-1 -> -0.009009009 | N8: 3429 | O8: 3492 | P8: 3504 | Q8: =P8/O8-1 -> 0.0034364261
A9: Mai | B9: 3219 | C9: 3157 | D9: 3337 | E9: =D9/C9-1 -> 0.057016155 | F9: 55 | G9: 42 | H9: 56 | I9: =H9/G9-1 -> 0.33333333 | J9: 211 | K9: 198 | L9: 227 | M9: =L9/K9-1 -> 0.14646465 | N9: 3850 | O9: 3623 | P9: 3864 | Q9: =P9/O9-1 -> 0.066519459
A10: Jun | B10: 2978 | C10: 3193 | D10: 3235 | E10: =D10/C10-1 -> 0.013153774 | F10: 48 | G10: 54 | H10: 49 | I10: =H10/G10-1 -> -0.092592593 | J10: 211 | K10: 245 | L10: 228 | M10: =L10/K10-1 -> -0.069387755 | N10: 3613 | O10: 3686 | P10: 3783 | Q10: =P10/O10-1 -> 0.026315789
A11: Jul | B11: 3397 | C11: 3525 | D11: 3587 | E11: =D11/C11-1 -> 0.017588652 | F11: 49 | G11: 66 | H11: 65 | I11: =H11/G11-1 -> -0.015151515 | J11: 221 | K11: 274 | L11: 274 | M11: =L11/K11-1 -> 0 | N11: 4147 | O11: 4226 | P11: 4179 | Q11: =P11/O11-1 -> -0.011121628
A12: Ago | B12: 3448 | C12: 3544 | D12: 3388 | E12: =D12/C12-1 -> -0.044018059 | F12: 75 | G12: 64 | H12: 72 | I12: =H12/G12-1 -> 0.125 | J12: 297 | K12: 285 | L12: 265 | M12: =L12/K12-1 -> -0.070175439 | N12: 4303 | O12: 4247 | P12: 4071 | Q12: =P12/O12-1 -> -0.041441017
A13: Set | B13: 3216 | C13: 3229 | D13: 3366 | E13: =D13/C13-1 -> 0.042427996 | F13: 65 | G13: 67 | H13: 64 | I13: =H13/G13-1 -> -0.044776119 | J13: 226 | K13: 210 | L13: 243 | M13: =L13/K13-1 -> 0.15714286 | N13: 3887 | O13: 3811 | P13: 3975 | Q13: =P13/O13-1 -> 0.043033325
A14: Out | B14: 3445 | C14: 3140 | D14: 3363 | E14: =D14/C14-1 -> 0.071019108 | F14: 56 | G14: 55 | H14: 45 | I14: =H14/G14-1 -> -0.18181818 | J14: 189 | K14: 187 | L14: 204 | M14: =L14/K14-1 -> 0.090909091 | N14: 4095 | O14: 3638 | P14: 4014 | Q14: =P14/O14-1 -> 0.10335349
A15: Nov | B15: 3203 | C15: 2974 | D15: 3111 | E15: =D15/C15-1 -> 0.046065905 | F15: 54 | G15: 29 | H15: 41 | I15: =H15/G15-1 -> 0.4137931 | J15: 180 | K15: 173 | L15: 212 | M15: =L15/K15-1 -> 0.22543353 | N15: 3814 | O15: 3487 | P15: 3687 | Q15: =P15/O15-1 -> 0.057355893
A16: Dez | B16: 3133 | C16: 2870 | D16: 3307 | E16: =D16/C16-1 -> 0.15226481 | F16: 53 | G16: 52 | H16: 54 | I16: =H16/G16-1 -> 0.038461538 | J16: 176 | K16: 194 | L16: 218 | M16: =L16/K16-1 -> 0.12371134 | N16: 3741 | O16: 3368 | P16: 3869 | Q16: =P16/O16-1 -> 0.14875297
A17: Total | B17: =SUM(B5:B16) -> 37251 | C17: 36595 | D17: =SUM(D5:D16) -> 38037 | E17: =D17/C17-1 -> 0.03940429 | F17: =SUM(F5:F16) -> 688 | G17: =SUM(G5:G16) -> 642 | H17: =SUM(H5:H16) -> 618 | I17: =H17/G17-1 -> -0.037383178 | J17: =SUM(J5:J16) -> 2383 | K17: =SUM(K5:K16) -> 2500 | L17: =SUM(L5:L16) -> 2626 | M17: =L17/K17-1 -> 0.0504 | N17: =SUM(N5:N16) -> 44934 | O17: =SUM(O5:O16) -> 42873 | P17: =SUM(P5:P16) -> 44607 | Q17: =P17/O17-1 -> 0.040445035

Sheet 1.2
A1: Quadro 1.2 Sinistralidade em Portugal por dia da semana
A3: Dia da semana | B3: AcV | F3: VM | J3: FG | N3: FL
B4: 2019 | C4: 2023 | D4: 2024 | E4: ∆(%) 24/23 | F4: 2019 | G4: 2023 | H4: 2024 | I4: ∆(%) 24/23 | J4: 2019 | K4: 2023 | L4: 2024 | M4: ∆(%) 24/23 | N4: 2019 | O4: 2023 | P4: 2024 | Q4: ∆(%) 24/23
A5: 2.ª feira | B5: 5279 | C5: 5315 | D5: 5499 | E5: =D5/C5-1 -> 0.034619003 | F5: 91 | G5: 83 | H5: 60 | I5: =H5/G5-1 -> -0.27710843 | J5: 255 | K5: 325 | L5: 355 | M5: =L5/K5-1 -> 0.092307692 | N5: 6330 | O5: 6116 | P5: 6365 | Q5: =P5/O5-1 -> 0.040712884
A6: 3.ª feira | B6: 5388 | C6: 5138 | D6: 5592 | E6: =D6/C6-1 -> 0.08836123 | F6: 84 | G6: 66 | H6: 81 | I6: =H6/G6-1 -> 0.22727273 | J6: 326 | K6: 302 | L6: 346 | M6: =L6/K6-1 -> 0.14569536 | N6: 6452 | O6: 5969 | P6: 6508 | Q6: =P6/O6-1 -> 0.090299883
A7: 4.ª feira | B7: 5333 | C7: 5235 | D7: 5611 | E7: =D7/C7-1 -> 0.07182426 | F7: 98 | G7: 62 | H7: 71 | I7: =H7/G7-1 -> 0.14516129 | J7: 284 | K7: 320 | L7: 362 | M7: =L7/K7-1 -> 0.13125 | N7: 6384 | O7: 6065 | P7: 6418 | Q7: =P7/O7-1 -> 0.058202803
A8: 5.ª feira | B8: 5593 | C8: 5229 | D8: 5436 | E8: =D8/C8-1 -> 0.039586919 | F8: 88 | G8: 87 | H8: 79 | I8: =H8/G8-1 -> -0.091954023 | J8: 303 | K8: 295 | L8: 294 | M8: =L8/K8-1 -> -0.0033898305 | N8: 6588 | O8: 6154 | P8: 6359 | Q8: =P8/O8-1 -> 0.033311667
A9: 6.ª feira | B9: 5789 | C9: 5814 | D9: 5981 | E9: =D9/C9-1 -> 0.02872377 | F9: 104 | G9: 91 | H9: 102 | I9: =H9/G9-1 -> 0.12087912 | J9: 365 | K9: 335 | L9: 393 | M9: =L9/K9-1 -> 0.17313433 | N9: 6901 | O9: 6796 | P9: 6954 | Q9: =P9/O9-1 -> 0.02324897
A10: Sábado | B10: 5274 | C10: 5173 | D10: 5181 | E10: =D10/C10-1 -> 0.0015464914 | F10: 108 | G10: 131 | H10: 100 | I10: =H10/G10-1 -> -0.23664122 | J10: 441 | K10: 481 | L10: 432 | M10: =L10/K10-1 -> -0.1018711 | N10: 6454 | O10: 6159 | P10: 6201 | Q10: =P10/O10-1 -> 0.0068192888
A11: Domingo | B11: 4595 | C11: 4691 | D11: 4737 | E11: =D11/C11-1 -> 0.0098060115 | F11: 115 | G11: 122 | H11: 125 | I11: =H11/G11-1 -> 0.024590164 | J11: 409 | K11: 442 | L11: 444 | M11: =L11/K11-1 -> 0.0045248869 | N11: 5825 | O11: 5614 | P11: 5802 | Q11: =P11/O11-1 -> 0.033487709
A12: Total | B12: =SUM(B5:B11) -> 37251 | C12: =SUM(C5:C11) -> 36595 | D12: =SUM(D5:D11) -> 38037 | E12: =D12/C12-1 -> 0.03940429 | F12: =SUM(F5:F11) -> 688 | G12: =SUM(G5:G11) -> 642 | H12: =SUM(H5:H11) -> 618 | I12: =H12/G12-1 -> -0.037383178 | J12: =SUM(J5:J11) -> 2383 | K12: =SUM(K5:K11) -> 2500 | L12: =SUM(L5:L11) -> 2626 | M12: =L12/K12-1 -> 0.0504 | N12: =SUM(N5:N11) -> 44934 | O12: =SUM(O5:O11) -> 42873 | P12: =SUM(P5:P11) -> 44607 | Q12: =P12/O12-1 -> 0.040445035

Sheet 1.3
A1: Quadro 1.3 Sinistralidade em Portugal por período horário
A3: Período horário | B3: AcV | F3: VM | J3: FG | N3: FL
B4: 2019 | C4: 2023 | D4: 2024 | E4: ∆(%) 24/23 | F4: 2019 | G4: 2023 | H4: 2024 | I4: ∆(%) 24/23 | J4: 2019 | K4: 2023 | L4: 2024 | M4: ∆(%) 24/23 | N4: 2019 | O4: 2023 | P4: 2024 | Q4: ∆(%) 24/23
A5: [00:00-03:00[ | B5: 1387 | C5: 1274 | D5: 1309 | E5: =D5/C5-1 -> 0.027472527 | F5: 43 | G5: 44 | H5: 43 | I5: =H5/G5-1 -> -0.022727273 | J5: 155 | K5: 145 | L5: 136 | M5: =L5/K5-1 -> -0.062068966 | N5: 1656 | O5: 1525 | P5: 1558 | Q5: =P5/O5-1 -> 0.021639344
A6: [03:00-06:00[ | B6: 797 | C6: 791 | D6: 779 | E6: =D6/C6-1 -> -0.01517067 | F6: 26 | G6: 39 | H6: 32 | I6: =H6/G6-1 -> -0.17948718 | J6: 99 | K6: 107 | L6: 82 | M6: =L6/K6-1 -> -0.23364486 | N6: 937 | O6: 915 | P6: 890 | Q6: =P6/O6-1 -> -0.027322404
A7: [06:00-09:00[ | B7: 4157 | C7: 4043 | D7: 4367 | E7: =D7/C7-1 -> 0.080138511 | F7: 57 | G7: 69 | H7: 86 | I7: =H7/G7-1 -> 0.24637681 | J7: 225 | K7: 242 | L7: 282 | M7: =L7/K7-1 -> 0.16528926 | N7: 4975 | O7: 4681 | P7: 5094 | Q7: =P7/O7-1 -> 0.088229011
A8: [09:00-12:00[ | B8: 6047 | C8: 6014 | D8: 6404 | E8: =D8/C8-1 -> 0.064848686 | F8: 83 | G8: 83 | H8: 65 | I8: =H8/G8-1 -> -0.21686747 | J8: 294 | K8: 292 | L8: 320 | M8: =L8/K8-1 -> 0.095890411 | N8: 7098 | O8: 6961 | P8: 7391 | Q8: =P8/O8-1 -> 0.061772734
A9: [12:00-15:00[ | B9: 6561 | C9: 6560 | D9: 6837 | E9: =D9/C9-1 -> 0.04222561 | F9: 78 | G9: 97 | H9: 83 | I9: =H9/G9-1 -> -0.1443299 | J9: 326 | K9: 411 | L9: 439 | M9: =L9/K9-1 -> 0.068126521 | N9: 7969 | O9: 7692 | P9: 8075 | Q9: =P9/O9-1 -> 0.049791992
A10: [15:00-18:00[ | B10: 7745 | C10: 7989 | D10: 8095 | E10: =D10/C10-1 -> 0.013268244 | F10: 142 | G10: 104 | H10: 112 | I10: =H10/G10-1 -> 0.076923077 | J10: 464 | K10: 560 | L10: 542 | M10: =L10/K10-1 -> -0.032142857 | N10: 9561 | O10: 9567 | P10: 9572 | Q10: =P10/O10-1 -> 0.00052262987
A11: [18:00-21:00[ | B11: 7463 | C11: 7198 | D11: 7282 | E11: =D11/C11-1 -> 0.011669908 | F11: 181 | G11: 149 | H11: 131 | I11: =H11/G11-1 -> -0.12080537 | J11: 534 | K11: 518 | L11: 579 | M11: =L11/K11-1 -> 0.11776062 | N11: 8971 | O11: 8314 | P11: 8528 | Q11: =P11/O11-1 -> 0.025739716
A12: [21:00-00:00[ | B12: 3094 | C12: 2726 | D12: 2964 | E12: =D12/C12-1 -> 0.08730741 | F12: 78 | G12: 57 | H12: 66 | I12: =H12/G12-1 -> 0.15789474 | J12: 286 | K12: 225 | L12: 246 | M12: =L12/K12-1 -> 0.093333333 | N12: 3767 | O12: 3218 | P12: 3499 | Q12: =P12/O12-1 -> 0.087321318
A13: Total | B13: =SUM(B5:B12) -> 37251 | C13: =SUM(C5:C12) -> 36595 | D13: =SUM(D5:D12) -> 38037 | E13: =D13/C13-1 -> 0.03940429 | F13: =SUM(F5:F12) -> 688 | G13: =SUM(G5:G12) -> 642 | H13: =SUM(H5:H12) -> 618 | I13: =H13/G13-1 -> -0.037383178 | J13: =SUM(J5:J12) -> 2383 | K13: =SUM(K5:K12) -> 2500 | L13: =SUM(L5:L12) -> 2626 | M13: =L13/K13-1 -> 0.0504 | N13: =SUM(N5:N12) -> 44934 | O13: =SUM(O5:O12) -> 42873 | P13: =SUM(P5:P12) -> 44607 | Q13: =P13/O13-1 -> 0.040445035

Sheet 1.4
A1: Quadro 1.4 Sinistralidade em Portugal por fatores atmosféricos
A3: Fatores atmosféricos | B3: AcV | F3: VM | J3: FG | N3: FL
B4: 2019 | C4: 2023 | D4: 2024 | E4: ∆(%) 24/23 | F4: 2019 | G4: 2023 | H4: 2024 | I4: ∆(%) 24/23 | J4: 2019 | K4: 2023 | L4: 2024 | M4: ∆(%) 24/23 | N4: 2019 | O4: 2023 | P4: 2024 | Q4: ∆(%) 24/23
A5: Bom tempo | B5: 29835 | C5: 30949 | D5: 31629 | E5: =D5/C5-1 -> 0.021971631 | F5: 593 | G5: 573 | H5: 544 | I5: =H5/G5-1 -> -0.05061082 | J5: 2031 | K5: 2221 | L5: 2271 | M5: =L5/K5-1 -> 0.022512382 | N5: 35778 | O5: 35960 | P5: 36834 | Q5: =P5/O5-1 -> 0.024304783
A6: Chuva | B6: 7055 | C6: 5320 | D6: 6074 | E6: =D6/C6-1 -> 0.14172932 | F6: 88 | G6: 60 | H6: 66 | I6: =H6/G6-1 -> 0.1 | J6: 313 | K6: 249 | L6: 330 | M6: =L6/K6-1 -> 0.3253012 | N6: 8682 | O6: 6489 | P6: 7379 | Q6: =P6/O6-1 -> 0.13715519
A7: Nevoeiro | B7: 234 | C7: 215 | D7: 210 | E7: =D7/C7-1 -> -0.023255814 | F7: 3 | G7: 6 | H7: 5 | I7: =H7/G7-1 -> -0.16666667 | J7: 30 | K7: 25 | L7: 20 | M7: =L7/K7-1 -> -0.2 | N7: 302 | O7: 296 | P7: 251 | Q7: =P7/O7-1 -> -0.15202703
A8: Vento | B8: 30 | C8: 38 | D8: 55 | E8: =D8/C8-1 -> 0.44736842 | F8: 1 | G8: 2 | H8: 3 | I8: =H8/G8-1 -> 0.5 | J8: 3 | K8: 2 | L8: 2 | M8: =L8/K8-1 -> 0 | N8: 29 | O8: 44 | P8: 57 | Q8: =P8/O8-1 -> 0.29545455
A9: Neve | B9: 8 | C9: 20 | D9: 7 | E9: =D9/C9-1 -> -0.65 | F9: 0 | G9: 1 | H9: 0 | I9: =H9/G9-1 -> -1 | J9: 0 | K9: 2 | L9: 0 | M9: =L9/K9-1 -> -1 | N9: 14 | O9: 23 | P9: 13 | Q9: =P9/O9-1 -> -0.43478261
A10: Fumo | B10: 5 | C10: 2 | D10: 2 | E10: =D10/C10-1 -> 0 | F10: 2 | G10: 0 | H10: 0 | I10: - | J10: 5 | K10: 0 | L10: 0 | M10: - | N10: 7 | O10: 2 | P10: 2 | Q10: =P10/O10-1 -> 0
A11: Granizo | B11: 31 | C11: 11 | D11: 19 | E11: =D11/C11-1 -> 0.72727273 | F11: 1 | G11: 0 | H11: 0 | I11: - | J11: 1 | K11: 1 | L11: 1 | M11: =L11/K11-1 -> 0 | N11: 55 | O11: 14 | P11: 30 | Q11: =P11/O11-1 -> 1.1428571
A12: n.d. | B12: 53 | C12: 40 | D12: 41 | E12: =D12/C12-1 -> 0.025 | F12: 0 | G12: 0 | H12: 0 | I12: - | J12: 0 | K12: 0 | L12: 2 | M12: - | N12: 67 | O12: 45 | P12: 41 | Q12: =P12/O12-1 -> -0.088888889
A13: Total | B13: =SUM(B5:B12) -> 37251 | C13: =SUM(C5:C12) -> 36595 | D13: =SUM(D5:D12) -> 38037 | E13: =D13/C13-1 -> 0.03940429 | F13: =SUM(F5:F12) -> 688 | G13: =SUM(G5:G12) -> 642 | H13: =SUM(H5:H12) -> 618 | I13: =H13/G13-1 -> -0.037383178 | J13: =SUM(J5:J12) -> 2383 | K13: =SUM(K5:K12) -> 2500 | L13: =SUM(L5:L12) -> 2626 | M13: =L13/K13-1 -> 0.0504 | N13: =SUM(N5:N12) -> 44934 | O13: =SUM(O5:O12) -> 42873 | P13: =SUM(P5:P12) -> 44607 | Q13: =P13/O13-1 -> 0.040445035
A14: n.d. - não definido

Sheet 1.5
A1: Quadro 1.5 Sinistralidade em Portugal por condições de luminosidade
A3: Luminosidade | B3: AcV | F3: VM | J3: FG | N3: FL
B4: 2019 | C4: 2023 | D4: 2024 | E4: ∆(%) 24/23 | F4: 2019 | G4: 2023 | H4: 2024 | I4: ∆(%) 24/23 | J4: 2019 | K4: 2023 | L4: 2024 | M4: ∆(%) 24/23 | N4: 2019 | O4: 2023 | P4: 2024 | Q4: ∆(%) 24/23
A5: Dia | B5: 26208 | C5: 26915 | D5: 27981 | E5: =D5/C5-1 -> 0.039606168 | F5: 406 | G5: 391 | H5: 368 | I5: =H5/G5-1 -> -0.058823529 | J5: 1434 | K5: 1686 | L5: 1761 | M5: =L5/K5-1 -> 0.044483986 | N5: 31690 | O5: 31560 | P5: 32851 | Q5: =P5/O5-1 -> 0.04090621
A6: Noite | B6: 9463 | C6: 8334 | D6: 9016 | E6: =D6/C6-1 -> 0.081833453 | F6: 256 | G6: 219 | H6: 222 | I6: =H6/G6-1 -> 0.01369863 | J6: 843 | K6: 715 | L6: 761 | M6: =L6/K6-1 -> 0.064335664 | N6: 11350 | O6: 9742 | P6: 10556 | Q6: =P6/O6-1 -> 0.083555738
A7: Aurora/Crepúsculo | B7: 1559 | C7: 1345 | D7: 1040 | E7: =D7/C7-1 -> -0.2267658 | F7: 26 | G7: 32 | H7: 28 | I7: =H7/G7-1 -> -0.125 | J7: 105 | K7: 99 | L7: 104 | M7: =L7/K7-1 -> 0.050505051 | N7: 1867 | O7: 1570 | P7: 1200 | Q7: =P7/O7-1 -> -0.23566879
A8: n.d. | B8: 21 | C8: 1 | D8: 0 | E8: =D8/C8-1 -> -1 | F8: 0 | G8: 0 | H8: 0 | I8: - | J8: 1 | K8: 0 | L8: 0 | M8: - | N8: 27 | O8: 1 | P8: 0 | Q8: =P8/O8-1 -> -1
A9: Total | B9: =SUM(B5:B8) -> 37251 | C9: =SUM(C5:C8) -> 36595 | D9: =SUM(D5:D8) -> 38037 | E9: =D9/C9-1 -> 0.03940429 | F9: =SUM(F5:F8) -> 688 | G9: =SUM(G5:G8) -> 642 | H9: =SUM(H5:H8) -> 618 | I9: =H9/G9-1 -> -0.037383178 | J9: =SUM(J5:J8) -> 2383 | K9: =SUM(K5:K8) -> 2500 | L9: =SUM(L5:L8) -> 2626 | M9: =L9/K9-1 -> 0.0504 | N9: =SUM(N5:N8) -> 44934 | O9: =SUM(O5:O8) -> 42873 | P9: =SUM(P5:P8) -> 44607 | Q9: =P9/O9-1 -> 0.040445035
A10: n.d. - não definido

Sheet 1.6
A1: Quadro 1.6 Sinistralidade em Portugal por natureza do acidente
A3: Natureza | B3: AcV | F3: VM | J3: FG | N3: FL
B4: 2019 | C4: 2023 | D4: 2024 | E4: ∆(%) 24/23 | F4: 2019 | G4: 2023 | H4: 2024 | I4: ∆(%) 24/23 | J4: 2019 | K4: 2023 | L4: 2024 | M4: ∆(%) 24/23 | N4: 2019 | O4: 2023 | P4: 2024 | Q4: ∆(%) 24/23
A5: Atropelamento | B5: 5565 | C5: 4873 | D5: 5073 | E5: =D5/C5-1 -> 0.041042479 | F5: 134 | G5: 106 | H5: 107 | I5: =H5/G5-1 -> 0.0094339623 | J5: 427 | K5: 346 | L5: 404 | M5: =L5/K5-1 -> 0.16763006 | N5: 5513 | O5: 4787 | P5: 5030 | Q5: =P5/O5-1 -> 0.050762482
A6: Colisão | B6: 19518 | C6: 19238 | D6: 20356 | E6: =D6/C6-1 -> 0.058114149 | F6: 265 | G6: 260 | H6: 275 | I6: =H6/G6-1 -> 0.057692308 | J6: 1012 | K6: 1152 | L6: 1214 | M6: =L6/K6-1 -> 0.053819444 | N6: 25880 | O6: 24565 | P6: 26016 | Q6: =P6/O6-1 -> 0.059067779
A7: Despiste | B7: 12168 | C7: 12484 | D7: 12608 | E7: =D7/C7-1 -> 0.0099327139 | F7: 289 | G7: 276 | H7: 236 | I7: =H7/G7-1 -> -0.14492754 | J7: 944 | K7: 1002 | L7: 1008 | M7: =L7/K7-1 -> 0.005988024 | N7: 13541 | O7: 13521 | P7: 13561 | Q7: =P7/O7-1 -> 0.0029583611
A8: Total | B8: =SUM(B5:B7) -> 37251 | C8: =SUM(C5:C7) -> 36595 | D8: =SUM(D5:D7) -> 38037 | E8: =D8/C8-1 -> 0.03940429 | F8: =SUM(F5:F7) -> 688 | G8: =SUM(G5:G7) -> 642 | H8: =SUM(H5:H7) -> 618 | I8: =H8/G8-1 -> -0.037383178 | J8: =SUM(J5:J7) -> 2383 | K8: =SUM(K5:K7) -> 2500 | L8: =SUM(L5:L7) -> 2626 | M8: =L8/K8-1 -> 0.0504 | N8: =SUM(N5:N7) -> 44934 | O8: =SUM(O5:O7) -> 42873 | P8: =SUM(P5:P7) -> 44607 | Q8: =P8/O8-1 -> 0.040445035

Sheet 1.7
A1: Quadro 1.7 Sinistralidade em Portugal por natureza detalhada do acidente
A3: Natureza | C3: AcV | G3: VM | K3: FG | O3: FL
C4: 2019 | D4: 2023 | E4: 2024 | F4: ∆(%) 24/23 | G4: 2019 | H4: 2023 | I4: 2024 | J4: ∆(%) 24/23 | K4: 2019 | L4: 2023 | M4: 2024 | N4: ∆(%) 24/23 | O4: 2019 | P4: 2023 | Q4: 2024 | R4: ∆(%) 24/23
A5: Atropelamento | B5: Atropelamento com fuga | C5: 495 | D5: 532 | E5: 602 | F5: =E5/D5-1 -> 0.13157895 | G5: 11 | H5: 11 | I5: 11 | J5: =I5/H5-1 -> 0 | K5: 36 | L5: 34 | M5: 39 | N5: =M5/L5-1 -> 0.14705882 | O5: 468 | P5: 514 | Q5: 583 | R5: =Q5/P5-1 -> 0.13424125
B6: Atropelamento de animais | C6: 71 | D6: 116 | E6: 128 | F6: =E6/D6-1 -> 0.10344828 | G6: 1 | H6: 0 | I6: 0 | J6: - | K6: 0 | L6: 4 | M6: 3 | N6: =M6/L6-1 -> -0.25 | O6: 75 | P6: 119 | Q6: 140 | R6: =Q6/P6-1 -> 0.17647059
B7: Atropelamento de peões | C7: 4999 | D7: 4225 | E7: 4343 | F7: =E7/D7-1 -> 0.027928994 | G7: 122 | H7: 95 | I7: 96 | J7: =I7/H7-1 -> 0.010526316 | K7: 391 | L7: 308 | M7: 362 | N7: =M7/L7-1 -> 0.17532468 | O7: 4970 | P7: 4154 | Q7: 4307 | R7: =Q7/P7-1 -> 0.036831969
B8: Total | C8: =SUM(C5:C7) -> 5565 | D8: =SUM(D5:D7) -> 4873 | E8: =SUM(E5:E7) -> 5073 | F8: =E8/D8-1 -> 0.041042479 | G8: =SUM(G5:G7) -> 134 | H8: =SUM(H5:H7) -> 106 | I8: =SUM(I5:I7) -> 107 | J8: =I8/H8-1 -> 0.0094339623 | K8: =SUM(K5:K7) -> 427 | L8: =SUM(L5:L7) -> 346 | M8: =SUM(M5:M7) -> 404 | N8: =M8/L8-1 -> 0.16763006 | O8: =SUM(O5:O7) -> 5513 | P8: =SUM(P5:P7) -> 4787 | Q8: =SUM(Q5:Q7) -> 5030 | R8: =Q8/P8-1 -> 0.050762482
A9: Colisão | B9: Colisão choque em cadeia | C9: 723 | D9: 665 | E9: 698 | F9: =E9/D9-1 -> 0.04962406 | G9: 6 | H9: 5 | I9: 1 | J9: =I9/H9-1 -> -0.8 | K9: 14 | L9: 15 | M9: 12 | N9: =M9/L9-1 -> -0.2 | O9: 1174 | P9: 1081 | Q9: 1107 | R9: =Q9/P9-1 -> 0.024051804
B10: Colisão com fuga | C10: 631 | D10: 689 | E10: 811 | F10: =E10/D10-1 -> 0.17706821 | G10: 3 | H10: 5 | I10: 8 | J10: =I10/H10-1 -> 0.6 | K10: 30 | L10: 28 | M10: 34 | N10: =M10/L10-1 -> 0.21428571 | O10: 739 | P10: 757 | Q10: 882 | R10: =Q10/P10-1 -> 0.1651255
B11: Colisão com outras situações | C11: 3269 | D11: 2384 | E11: 2540 | F11: =E11/D11-1 -> 0.065436242 | G11: 33 | H11: 22 | I11: 19 | J11: =I11/H11-1 -> -0.13636364 | K11: 136 | L11: 122 | M11: 119 | N11: =M11/L11-1 -> -0.024590164 | O11: 4214 | P11: 2886 | Q11: 3090 | R11: =Q11/P11-1 -> 0.070686071
B12: Colisão com veiculo ou obstáculo na faixa de rodagem | C12: 1067 | D12: 1412 | E12: 1511 | F12: =E12/D12-1 -> 0.070113314 | G12: 13 | H12: 20 | I12: 23 | J12: =I12/H12-1 -> 0.15 | K12: 57 | L12: 95 | M12: 99 | N12: =M12/L12-1 -> 0.042105263 | O12: 1323 | P12: 1743 | Q12: 1823 | R12: =Q12/P12-1 -> 0.045897877
B13: Colisão frontal | C13: 2834 | D13: 2779 | E13: 2987 | F13: =E13/D13-1 -> 0.074847067 | G13: 110 | H13: 111 | I13: 120 | J13: =I13/H13-1 -> 0.081081081 | K13: 326 | L13: 368 | M13: 414 | N13: =M13/L13-1 -> 0.125 | O13: 4271 | P13: 4084 | Q13: 4455 | R13: =Q13/P13-1 -> 0.090842311
B14: Colisão lateral com outro veículo em movimento | C14: 6714 | D14: 7231 | E14: 7477 | F14: =E14/D14-1 -> 0.034020191 | G14: 63 | H14: 64 | I14: 69 | J14: =I14/H14-1 -> 0.078125 | K14: 298 | L14: 400 | M14: 393 | N14: =M14/L14-1 -> -0.0175 | O14: 8460 | P14: 8683 | Q14: 9104 | R14: =Q14/P14-1 -> 0.048485546
B15: Colisão traseira com outro veículo em movimento | C15: 4280 | D15: 4078 | E15: 4332 | F15: =E15/D15-1 -> 0.062285434 | G15: 37 | H15: 33 | I15: 35 | J15: =I15/H15-1 -> 0.060606061 | K15: 151 | L15: 124 | M15: 143 | N15: =M15/L15-1 -> 0.15322581 | O15: 5699 | P15: 5331 | Q15: 5555 | R15: =Q15/P15-1 -> 0.042018383
B16: Total | C16: =SUM(C9:C15) -> 19518 | D16: =SUM(D9:D15) -> 19238 | E16: =SUM(E9:E15) -> 20356 | F16: =E16/D16-1 -> 0.058114149 | G16: =SUM(G9:G15) -> 265 | H16: =SUM(H9:H15) -> 260 | I16: =SUM(I9:I15) -> 275 | J16: =I16/H16-1 -> 0.057692308 | K16: =SUM(K9:K15) -> 1012 | L16: =SUM(L9:L15) -> 1152 | M16: =SUM(M9:M15) -> 1214 | N16: =M16/L16-1 -> 0.053819444 | O16: =SUM(O9:O15) -> 25880 | P16: =SUM(P9:P15) -> 24565 | Q16: =SUM(Q9:Q15) -> 26016 | R16: =Q16/P16-1 -> 0.059067779
A17: Despiste | B17: Despiste com capotamento | C17: 2060 | D17: 2161 | E17: 2206 | F17: =E17/D17-1 -> 0.020823693 | G17: 105 | H17: 65 | I17: 51 | J17: =I17/H17-1 -> -0.21538462 | K17: 225 | L17: 205 | M17: 221 | N17: =M17/L17-1 -> 0.07804878 | O17: 2554 | P17: 2589 | Q17: 2591 | R17: =Q17/P17-1 -> 0.00077249903
B18: Despiste com colisão com veículo imobil. ou obstáculo | C18: 1193 | D18: 1583 | E18: 1632 | F18: =E18/D18-1 -> 0.030953885 | G18: 31 | H18: 52 | I18: 44 | J18: =I18/H18-1 -> -0.15384615 | K18: 106 | L18: 152 | M18: 162 | N18: =M18/L18-1 -> 0.065789474 | O18: 1336 | P18: 1718 | Q18: 1783 | R18: =Q18/P18-1 -> 0.037834692
B19: Despiste com dispositivo de retenção | C19: 570 | D19: 468 | E19: 457 | F19: =E19/D19-1 -> -0.023504274 | G19: 1 | H19: 9 | I19: 5 | J19: =I19/H19-1 -> -0.44444444 | K19: 21 | L19: 39 | M19: 27 | N19: =M19/L19-1 -> -0.30769231 | O19: 630 | P19: 519 | Q19: 501 | R19: =Q19/P19-1 -> -0.034682081
B20: Despiste com fuga | C20: 101 | D20: 133 | E20: 127 | F20: =E20/D20-1 -> -0.045112782 | G20: 0 | H20: 5 | I20: 1 | J20: =I20/H20-1 -> -0.8 | K20: 19 | L20: 7 | M20: 9 | N20: =M20/L20-1 -> 0.28571429 | O20: 111 | P20: 143 | Q20: 137 | R20: =Q20/P20-1 -> -0.041958042
B21: Despiste com transposição do dispositivo de retenção lateral | C21: 189 | D21: 173 | E21: 175 | F21: =E21/D21-1 -> 0.011560694 | G21: 13 | H21: 9 | I21: 8 | J21: =I21/H21-1 -> -0.11111111 | K21: 18 | L21: 25 | M21: 25 | N21: =M21/L21-1 -> 0 | O21: 227 | P21: 191 | Q21: 206 | R21: =Q21/P21-1 -> 0.078534031
B22: Despiste sem dispositivo de retenção | C22: 1892 | D22: 1949 | E22: 1899 | F22: =E22/D22-1 -> -0.025654182 | G22: 20 | H22: 21 | I22: 8 | J22: =I22/H22-1 -> -0.61904762 | K22: 100 | L22: 98 | M22: 97 | N22: =M22/L22-1 -> -0.010204082 | O22: 1975 | P22: 2020 | Q22: 1967 | R22: =Q22/P22-1 -> -0.026237624
B23: Despiste simples | C23: 6163 | D23: 6017 | E23: 6112 | F23: =E23/D23-1 -> 0.015788599 | G23: 119 | H23: 115 | I23: 119 | J23: =I23/H23-1 -> 0.034782609 | K23: 455 | L23: 476 | M23: 467 | N23: =M23/L23-1 -> -0.018907563 | O23: 6708 | P23: 6341 | Q23: 6376 | R23: =Q23/P23-1 -> 0.0055196341
B24: Total | C24: =SUM(C17:C23) -> 12168 | D24: =SUM(D17:D23) -> 12484 | E24: =SUM(E17:E23) -> 12608 | F24: =E24/D24-1 -> 0.0099327139 | G24: =SUM(G17:G23) -> 289 | H24: =SUM(H17:H23) -> 276 | I24: =SUM(I17:I23) -> 236 | J24: =I24/H24-1 -> -0.14492754 | K24: =SUM(K17:K23) -> 944 | L24: =SUM(L17:L23) -> 1002 | M24: =SUM(M17:M23) -> 1008 | N24: =M24/L24-1 -> 0.005988024 | O24: =SUM(O17:O23) -> 13541 | P24: =SUM(P17:P23) -> 13521 | Q24: =SUM(Q17:Q23) -> 13561 | R24: =Q24/P24-1 -> 0.0029583611
A25: Total | C25: =C24+C16+C8 -> 37251 | D25: =D24+D16+D8 -> 36595 | E25: =E24+E16+E8 -> 38037 | F25: =E25/D25-1 -> 0.03940429 | G25: =G24+G16+G8 -> 688 | H25: =H24+H16+H8 -> 642 | I25: =I24+I16+I8 -> 618 | J25: =I25/H25-1 -> -0.037383178 | K25: =K24+K16+K8 -> 2383 | L25: =L24+L16+L8 -> 2500 | M25: =M24+M16+M8 -> 2626 | N25: =M25/L25-1 -> 0.0504 | O25: =O24+O16+O8 -> 44934 | P25: =P24+P16+P8 -> 42873 | Q25: =Q24+Q16+Q8 -> 44607 | R25: =Q25/P25-1 -> 0.040445035

Sheet 1.8
A1: Quadro 1.8 Sinistralidade em Portugal por localização do acidente
A3: Localização | B3: AcV | F3: VM | J3: FG | N3: FL
B4: 2019 | C4: 2023 | D4: 2024 | E4: ∆(%) 24/23 | F4: 2019 | G4: 2023 | H4: 2024 | I4: ∆(%) 24/23 | J4: 2019 | K4: 2023 | L4: 2024 | M4: ∆(%) 24/23 | N4: 2019 | O4: 2023 | P4: 2024 | Q4: ∆(%) 24/23
A5: Dentro das localidades | B5: 29438 | C5: 28983 | D5: 30075 | E5: =D5/C5-1 -> 0.037677259 | F5: 394 | G5: 350 | H5: 355 | I5: =H5/G5-1 -> 0.014285714 | J5: 1559 | K5: 1682 | L5: 1782 | M5: =L5/K5-1 -> 0.059453032 | N5: 34669 | O5: 33107 | P5: 34481 | Q5: =P5/O5-1 -> 0.041501797
A6: Fora das localidades | B6: 7813 | C6: 7612 | D6: 7962 | E6: =D6/C6-1 -> 0.045980032 | F6: 294 | G6: 292 | H6: 263 | I6: =H6/G6-1 -> -0.099315068 | J6: 824 | K6: 818 | L6: 844 | M6: =L6/K6-1 -> 0.031784841 | N6: 10265 | O6: 9766 | P6: 10126 | Q6: =P6/O6-1 -> 0.036862584
A7: Total | B7: =SUM(B5:B6) -> 37251 | C7: =SUM(C5:C6) -> 36595 | D7: =SUM(D5:D6) -> 38037 | E7: =D7/C7-1 -> 0.03940429 | F7: =SUM(F5:F6) -> 688 | G7: =SUM(G5:G6) -> 642 | H7: =SUM(H5:H6) -> 618 | I7: =H7/G7-1 -> -0.037383178 | J7: =SUM(J5:J6) -> 2383 | K7: =SUM(K5:K6) -> 2500 | L7: =SUM(L5:L6) -> 2626 | M7: =L7/K7-1 -> 0.0504 | N7: =SUM(N5:N6) -> 44934 | O7: =SUM(O5:O6) -> 42873 | P7: =SUM(P5:P6) -> 44607 | Q7: =P7/O7-1 -> 0.040445035

Sheet 1.9
A1: Quadro 1.9 Sinistralidade em Portugal por tipo de via
A3: Tipo de via | B3: AcV | F3: VM | J3: FG | N3: FL
B4: 2019 | C4: 2023 | D4: 2024 | E4: ∆(%) 24/23 | F4: 2019 | G4: 2023 | H4: 2024 | I4: ∆(%) 24/23 | J4: 2019 | K4: 2023 | L4: 2024 | M4: ∆(%) 24/23 | N4: 2019 | O4: 2023 | P4: 2024 | Q4: ∆(%) 24/23
A5: AE | B5: 2146 | C5: 2010 | D5: 2172 | E5: =D5/C5-1 -> 0.080597015 | F5: 67 | G5: 49 | H5: 46 | I5: =H5/G5-1 -> -0.06122449 | J5: 168 | K5: 150 | L5: 150 | M5: =L5/K5-1 -> 0 | N5: 3084 | O5: 2836 | P5: 3024 | Q5: =P5/O5-1 -> 0.06629055
A6: Arruamento | B6: 24298 | C6: 22986 | D6: 23819 | E6: =D6/C6-1 -> 0.03623945 | F6: 295 | G6: 221 | H6: 211 | I6: =H6/G6-1 -> -0.045248869 | J6: 1204 | K6: 1158 | L6: 1241 | M6: =L6/K6-1 -> 0.071675302 | N6: 28157 | O6: 25828 | P6: 26924 | Q6: =P6/O6-1 -> 0.042434567
A7: EM | B7: 1335 | C7: 1264 | D7: 1234 | E7: =D7/C7-1 -> -0.023734177 | F7: 40 | G7: 31 | H7: 32 | I7: =H7/G7-1 -> 0.032258065 | J7: 157 | K7: 135 | L7: 144 | M7: =L7/K7-1 -> 0.066666667 | N7: 1609 | O7: 1481 | P7: 1376 | Q7: =P7/O7-1 -> -0.070898042
A8: EN | B8: 6372 | C8: 6965 | D8: 7229 | E8: =D8/C8-1 -> 0.037903805 | F8: 180 | G8: 199 | H8: 217 | I8: =H8/G8-1 -> 0.090452261 | J8: 549 | K8: 716 | L8: 734 | M8: =L8/K8-1 -> 0.025139665 | N8: 8241 | O8: 8668 | P8: 8985 | Q8: =P8/O8-1 -> 0.036571297
A9: ER | B9: 361 | C9: 509 | D9: 515 | E9: =D9/C9-1 -> 0.011787819 | F9: 10 | G9: 22 | H9: 12 | I9: =H9/G9-1 -> -0.45454545 | J9: 32 | K9: 72 | L9: 70 | M9: =L9/K9-1 -> -0.027777778 | N9: 468 | O9: 613 | P9: 639 | Q9: =P9/O9-1 -> 0.042414356
A10: IC | B10: 966 | C10: 829 | D10: 948 | E10: =D10/C10-1 -> 0.14354644 | F10: 31 | G10: 41 | H10: 34 | I10: =H10/G10-1 -> -0.17073171 | J10: 82 | K10: 67 | L10: 76 | M10: =L10/K10-1 -> 0.13432836 | N10: 1265 | O10: 1101 | P10: 1206 | Q10: =P10/O10-1 -> 0.095367847
A11: IP | B11: 263 | C11: 218 | D11: 242 | E11: =D11/C11-1 -> 0.11009174 | F11: 19 | G11: 17 | H11: 11 | I11: =H11/G11-1 -> -0.35294118 | J11: 26 | K11: 26 | L11: 24 | M11: =L11/K11-1 -> -0.076923077 | N11: 349 | O11: 269 | P11: 326 | Q11: =P11/O11-1 -> 0.21189591
A12: Outras vias* | B12: 1510 | C12: 1814 | D12: 1878 | E12: =D12/C12-1 -> 0.035281147 | F12: 46 | G12: 62 | H12: 55 | I12: =H12/G12-1 -> -0.11290323 | J12: 165 | K12: 176 | L12: 187 | M12: =L12/K12-1 -> 0.0625 | N12: 1761 | O12: 2077 | P12: 2127 | Q12: =P12/O12-1 -> 0.024073182
A13: Total | B13: =SUM(B5:B12) -> 37251 | C13: =SUM(C5:C12) -> 36595 | D13: =SUM(D5:D12) -> 38037 | E13: =D13/C13-1 -> 0.03940429 | F13: =SUM(F5:F12) -> 688 | G13: =SUM(G5:G12) -> 642 | H13: =SUM(H5:H12) -> 618 | I13: =H13/G13-1 -> -0.037383178 | J13: =SUM(J5:J12) -> 2383 | K13: =SUM(K5:K12) -> 2500 | L13: =SUM(L5:L12) -> 2626 | M13: =L13/K13-1 -> 0.0504 | N13: =SUM(N5:N12) -> 44934 | O13: =SUM(O5:O12) -> 42873 | P13: =SUM(P5:P12) -> 44607 | Q13: =P13/O13-1 -> 0.040445035
A14: *Inclui acessos, estradas florestais, pontes, variantes e não definidas

Sheet 1.10
A1: Quadro 1.10 Sinistralidade em Portugal por distrito e R.A.
A3: Distrito e R.A. | B3: AcV | F3: VM | J3: FG | N3: FL
B4: 2019 | C4: 2023 | D4: 2024 | E4: ∆(%) 24/23 | F4: 2019 | G4: 2023 | H4: 2024 | I4: ∆(%) 24/23 | J4: 2019 | K4: 2023 | L4: 2024 | M4: ∆(%) 24/23 | N4: 2019 | O4: 2023 | P4: 2024 | Q4: ∆(%) 24/23
A5: Aveiro | B5: 2815 | C5: 2868 | D5: 2898 | E5: =D5/C5-1 -> 0.010460251 | F5: 42 | G5: 44 | H5: 39 | I5: =H5/G5-1 -> -0.11363636 | J5: 135 | K5: 189 | L5: 190 | M5: =L5/K5-1 -> 0.0052910053 | N5: 3362 | O5: 3339 | P5: 3385 | Q5: =P5/O5-1 -> 0.01377658
A6: Beja | B6: 468 | C6: 486 | D6: 520 | E6: =D6/C6-1 -> 0.069958848 | F6: 37 | G6: 28 | H6: 28 | I6: =H6/G6-1 -> 0 | J6: 68 | K6: 83 | L6: 106 | M6: =L6/K6-1 -> 0.27710843 | N6: 566 | O6: 570 | P6: 578 | Q6: =P6/O6-1 -> 0.014035088
A7: Braga | B7: 3180 | C7: 3291 | D7: 3312 | E7: =D7/C7-1 -> 0.0063810392 | F7: 45 | G7: 50 | H7: 44 | I7: =H7/G7-1 -> -0.12 | J7: 153 | K7: 181 | L7: 220 | M7: =L7/K7-1 -> 0.21546961 | N7: 3988 | O7: 3951 | P7: 4028 | Q7: =P7/O7-1 -> 0.019488737
A8: Bragança | B8: 412 | C8: 394 | D8: 393 | E8: =D8/C8-1 -> -0.0025380711 | F8: 8 | G8: 7 | H8: 10 | I8: =H8/G8-1 -> 0.42857143 | J8: 48 | K8: 47 | L8: 48 | M8: =L8/K8-1 -> 0.021276596 | N8: 488 | O8: 472 | P8: 469 | Q8: =P8/O8-1 -> -0.0063559322
A9: C. Branco | B9: 527 | C9: 565 | D9: 547 | E9: =D9/C9-1 -> -0.031858407 | F9: 14 | G9: 24 | H9: 14 | I9: =H9/G9-1 -> -0.41666667 | J9: 66 | K9: 72 | L9: 64 | M9: =L9/K9-1 -> -0.11111111 | N9: 628 | O9: 660 | P9: 616 | Q9: =P9/O9-1 -> -0.066666667
A10: Coimbra | B10: 1624 | C10: 1602 | D10: 1635 | E10: =D10/C10-1 -> 0.020599251 | F10: 40 | G10: 36 | H10: 32 | I10: =H10/G10-1 -> -0.11111111 | J10: 79 | K10: 83 | L10: 103 | M10: =L10/K10-1 -> 0.24096386 | N10: 1952 | O10: 1856 | P10: 1897 | Q10: =P10/O10-1 -> 0.022090517
A11: Évora | B11: 444 | C11: 458 | D11: 515 | E11: =D11/C11-1 -> 0.12445415 | F11: 17 | G11: 12 | H11: 16 | I11: =H11/G11-1 -> 0.33333333 | J11: 71 | K11: 76 | L11: 68 | M11: =L11/K11-1 -> -0.10526316 | N11: 545 | O11: 532 | P11: 591 | Q11: =P11/O11-1 -> 0.11090226
A12: Faro | B12: 2154 | C12: 2149 | D12: 2363 | E12: =D12/C12-1 -> 0.099581201 | F12: 44 | G12: 43 | H12: 43 | I12: =H12/G12-1 -> 0 | J12: 214 | K12: 184 | L12: 199 | M12: =L12/K12-1 -> 0.081521739 | N12: 2449 | O12: 2401 | P12: 2606 | Q12: =P12/O12-1 -> 0.085381091
A13: Guarda | B13: 433 | C13: 440 | D13: 480 | E13: =D13/C13-1 -> 0.090909091 | F13: 19 | G13: 15 | H13: 19 | I13: =H13/G13-1 -> 0.26666667 | J13: 58 | K13: 50 | L13: 48 | M13: =L13/K13-1 -> -0.04 | N13: 509 | O13: 527 | P13: 558 | Q13: =P13/O13-1 -> 0.058823529
A14: Leiria | B14: 1822 | C14: 1802 | D14: 1857 | E14: =D14/C14-1 -> 0.030521643 | F14: 45 | G14: 38 | H14: 45 | I14: =H14/G14-1 -> 0.18421053 | J14: 123 | K14: 151 | L14: 177 | M14: =L14/K14-1 -> 0.17218543 | N14: 2132 | O14: 2117 | P14: 2120 | Q14: =P14/O14-1 -> 0.0014170997
A15: Lisboa | B15: 8232 | C15: 7248 | D15: 7694 | E15: =D15/C15-1 -> 0.061534216 | F15: 76 | G15: 60 | H15: 76 | I15: =H15/G15-1 -> 0.26666667 | J15: 337 | K15: 298 | L15: 313 | M15: =L15/K15-1 -> 0.05033557 | N15: 9820 | O15: 8460 | P15: 9035 | Q15: =P15/O15-1 -> 0.067966903
A16: Portalegre | B16: 303 | C16: 331 | D16: 326 | E16: =D16/C16-1 -> -0.01510574 | F16: 17 | G16: 19 | H16: 11 | I16: =H16/G16-1 -> -0.42105263 | J16: 52 | K16: 41 | L16: 62 | M16: =L16/K16-1 -> 0.51219512 | N16: 365 | O16: 389 | P16: 364 | Q16: =P16/O16-1 -> -0.064267352
... A24: R.A. Madeira | B24: 936 | C24: 1001 | D24: 1018 | E24: =D24/C24-1 -> 0.016983017 | F24: 41 | G24: 11 | H24: 11 | I24: =H24/G24-1 -> 0 | J24: 109 | K24: 97 | L24: 73 | M24: =L24/K24-1 -> -0.24742268 | N24: 1065 | O24: 1124 | P24: 1159 | Q24: =P24/O24-1 -> 0.03113879
A25: Total | B25: =SUM(B5:B24) -> 37251 | C25: =SUM(C5:C24) -> 36595 | D25: =SUM(D5:D24) -> 38037 | E25: =D25/C25-1 -> 0.03940429 | F25: =SUM(F5:F24) -> 688 | G25: =SUM(G5:G24) -> 642 | H25: =SUM(H5:H24) -> 618 | I25: =H25/G25-1 -> -0.037383178 | J25: =SUM(J5:J24) -> 2383 | K25: =SUM(K5:K24) -> 2500 | L25: =SUM(L5:L24) -> 2626 | M25: =L25/K25-1 -> 0.0504 | N25: =SUM(N5:N24) -> 44934 | O25: =SUM(O5:O24) -> 42873 | P25: =SUM(P5:P24) -> 44607 | Q25: =P25/O25-1 -> 0.040445035

Sheet 2.1
A1: Quadro 2.1 Veículos intervenientes em acidentes com vítimas em Portugal por categoria e natureza do acidente
A3: Categoria veículo e natureza | C3: Atropelamento | G3: Colisão | K3: Despiste | O3: Total
C4: 2019 | D4: 2023 | E4: 2024 | F4: ∆(%) 24/23 | G4: 2019 | H4: 2023 | I4: 2024 | J4: ∆(%) 24/23 | K4: 2019 | L4: 2023 | M4: 2024 | N4: ∆(%) 24/23 | O4: 2019 | P4: 2023 | Q4: 2024 | R4: ∆(%) 24/23
A5: Veículo Ligeiro | B5: Passageiros | C5: 3999 | D5: 3421 | E5: 3550 | F5: =E5/D5-1 -> 0.037708272 | G5: 26869 | H5: 24957 | I5: 26450 | J5: =I5/H5-1 -> 0.059822895 | K5: 6460 | L5: 6510 | M5: 6496 | N5: =M5/L5-1 -> -0.0021505376 | O5: =C5+G5+K5 -> 37328 | P5: =D5+H5+L5 -> 34888 | Q5: =E5+I5+M5 -> 36496 | R5: =Q5/P5-1 -> 0.046090346
B6: Mercadorias | C6: 822 | D6: 753 | E6: 693 | F6: =E6/D6-1 -> -0.079681275 | G6: 5528 | H6: 5178 | I6: 5101 | J6: =I6/H6-1 -> -0.014870606 | K6: 1376 | L6: 1231 | M6: 1192 | N6: =M6/L6-1 -> -0.03168156 | O6: =C6+G6+K6 -> 7726 | P6: =D6+H6+L6 -> 7162 | Q6: =E6+I6+M6 -> 6986 | R6: =Q6/P6-1 -> -0.024574141
B7: Outros | C7: 35 | D7: 40 | E7: 25 | F7: =E7/D7-1 -> -0.375 | G7: 322 | H7: 256 | I7: 262 | J7: =I7/H7-1 -> 0.0234375 | K7: 94 | L7: 48 | M7: 63 | N7: =M7/L7-1 -> 0.3125 | O7: =C7+G7+K7 -> 451 | P7: =D7+H7+L7 -> 344 | Q7: =E7+I7+M7 -> 350 | R7: =Q7/P7-1 -> 0.01744186
B8: n.d. | C8: 108 | D8: 103 | E8: 116 | F8: =E8/D8-1 -> 0.12621359 | G8: 39 | H8: 38 | I8: 43 | J8: =I8/H8-1 -> 0.13157895 | K8: 13 | L8: 6 | M8: 4 | N8: =M8/L8-1 -> -0.33333333 | O8: =C8+G8+K8 -> 160 | P8: =D8+H8+L8 -> 147 | Q8: =E8+I8+M8 -> 163 | R8: =Q8/P8-1 -> 0.10884354
B9: Total | C9: =SUM(C5:C8) -> 4964 | D9: =SUM(D5:D8) -> 4317 | E9: =SUM(E5:E8) -> 4384 | F9: =E9/D9-1 -> 0.015520037 | G9: =SUM(G5:G8) -> 32758 | H9: =SUM(H5:H8) -> 30429 | I9: =SUM(I5:I8) -> 31856 | J9: =I9/H9-1 -> 0.046896053 | K9: =SUM(K5:K8) -> 7943 | L9: =SUM(L5:L8) -> 7795 | M9: =SUM(M5:M8) -> 7755 | N9: =M9/L9-1 -> -0.0051314945 | O9: =SUM(O5:O8) -> 45665 | P9: =SUM(P5:P8) -> 42541 | Q9: =SUM(Q5:Q8) -> 43995 | R9: =Q9/P9-1 -> 0.034178792
A10: Veículo Pesado | B10: Passageiros | C10: 104 | D10: 109 | E10: 122 | F10: =E10/D10-1 -> 0.11926606 | G10: 364 | H10: 353 | I10: 415 | J10: =I10/H10-1 -> 0.17563739 | K10: 26 | L10: 31 | M10: 27 | N10: =M10/L10-1 -> -0.12903226 | O10: =C10+G10+K10 -> 494 | P10: =D10+H10+L10 -> 493 | Q10: =E10+I10+M10 -> 564 | R10: =Q10/P10-1 -> 0.14401623
B11: Mercadorias | C11: 50 | D11: 38 | E11: 37 | F11: =E11/D11-1 -> -0.026315789 | G11: 590 | H11: 579 | I11: 586 | J11: =I11/H11-1 -> 0.01208981 | K11: 131 | L11: 102 | M11: 125 | N11: =M11/L11-1 -> 0.2254902 | O11: =C11+G11+K11 -> 771 | P11: =D11+H11+L11 -> 719 | Q11: =E11+I11+M11 -> 748 | R11: =Q11/P11-1 -> 0.040333797
B12: Outros | C12: 21 | D12: 17 | E12: 17 | F12: =E12/D12-1 -> 0 | G12: 314 | H12: 298 | I12: 343 | J12: =I12/H12-1 -> 0.15100671 | K12: 75 | L12: 63 | M12: 76 | N12: =M12/L12-1 -> 0.20634921 | O12: =C12+G12+K12 -> 410 | P12: =D12+H12+L12 -> 378 | Q12: =E12+I12+M12 -> 436 | R12: =Q12/P12-1 -> 0.15343915
B13: n.d. | C13: 3 | D13: 1 | E13: 0 | F13: =E13/D13-1 -> -1 | G13: 1 | H13: 1 | I13: 1 | J13: =I13/H13-1 -> 0 | K13: 0 | L13: 0 | M13: 0 | N13: - | O13: =C13+G13+K13 -> 4 | P13: =D13+H13+L13 -> 2 | Q13: =E13+I13+M13 -> 1 | R13: =Q13/P13-1 -> -0.5
B14: Total | C14: =SUM(C10:C13) -> 178 | D14: =SUM(D10:D13) -> 165 | E14: =SUM(E10:E13) -> 176 | F14: =E14/D14-1 -> 0.066666667 | G14: =SUM(G10:G13) -> 1269 | H14: =SUM(H10:H13) -> 1231 | I14: =SUM(I10:I13) -> 1345 | J14: =I14/H14-1 -> 0.092607636 | K14: =SUM(K10:K13) -> 232 | L14: =SUM(L10:L13) -> 196 | M14: =SUM(M10:M13) -> 228 | N14: =M14/L14-1 -> 0.16326531 | O14: =SUM(O10:O13) -> 1679 | P14: =SUM(P10:P13) -> 1592 | Q14: =SUM(Q10:Q13) -> 1749 | R14: =Q14/P14-1 -> 0.09861809
A15: Ciclomotor | C15: 73 | D15: 32 | E15: 36 | F15: =E15/D15-1 -> 0.125 | G15: 1399 | H15: 1011 | I15: 939 | J15: =I15/H15-1 -> -0.071216617 | K15: 1034 | L15: 842 | M15: 704 | N15: =M15/L15-1 -> -0.16389549 | O15: =C15+G15+K15 -> 2506 | P15: =D15+H15+L15 -> 1885 | Q15: =E15+I15+M15 -> 1679 | R15: =Q15/P15-1 -> -0.10928382
A16: Motociclo cilindrada <= 125cc | C16: 136 | D16: 146 | E16: 175 | F16: =E16/D16-1 -> 0.19863014 | G16: 2694 | H16: 3450 | I16: 3658 | J16: =I16/H16-1 -> 0.060289855 | K16: 1621 | L16: 1924 | M16: 2045 | N16: =M16/L16-1 -> 0.062889813 | O16: =C16+G16+K16 -> 4451 | P16: =D16+H16+L16 -> 5520 | Q16: =E16+I16+M16 -> 5878 | R16: =Q16/P16-1 -> 0.064855072
A17: Motociclo cilindrada > 125cc | C17: 93 | D17: 89 | E17: 115 | F17: =E17/D17-1 -> 0.29213483 | G17: 1898 | H17: 2437 | I17: 2613 | J17: =I17/H17-1 -> 0.072219943 | K17: 1096 | L17: 1396 | M17: 1510 | N17: =M17/L17-1 -> 0.081661891 | O17: =C17+G17+K17 -> 3087 | P17: =D17+H17+L17 -> 3922 | Q17: =E17+I17+M17 -> 4238 | R17: =Q17/P17-1 -> 0.080571137
A18: Velocípede | C18: 139 | D18: 149 | E18: 155 | F18: =E18/D18-1 -> 0.040268456 | G18: 1612 | H18: 2132 | I18: 2401 | J18: =I18/H18-1 -> 0.12617261 | K18: 680 | L18: 1048 | M18: 1145 | N18: =M18/L18-1 -> 0.092557252 | O18: =C18+G18+K18 -> 2431 | P18: =D18+H18+L18 -> 3329 | Q18: =E18+I18+M18 -> 3701 | R18: =Q18/P18-1 -> 0.11174527
A19: Quadriciclo | C19: 15 | D19: 15 | E19: 22 | F19: =E19/D19-1 -> 0.46666667 | G19: 125 | H19: 119 | I19: 117 | J19: =I19/H19-1 -> -0.016806723 | K19: 207 | L19: 143 | M19: 152 | N19: =M19/L19-1 -> 0.062937063 | O19: =C19+G19+K19 -> 347 | P19: =D19+H19+L19 -> 277 | Q19: =E19+I19+M19 -> 291 | R19: =Q19/P19-1 -> 0.050541516
A20: Triciclo | C20: 10 | D20: 5 | E20: 10 | F20: =E20/D20-1 -> 1 | G20: 23 | H20: 21 | I20: 19 | J20: =I20/H20-1 -> -0.095238095 | K20: 14 | L20: 15 | M20: 14 | N20: =M20/L20-1 -> -0.066666667 | O20: =C20+G20+K20 -> 47 | P20: =D20+H20+L20 -> 41 | Q20: =E20+I20+M20 -> 43 | R20: =Q20/P20-1 -> 0.048780488
A21: Veículo agrícola | C21: 10 | D21: 5 | E21: 14 | F21: =E21/D21-1 -> 1.8 | G21: 113 | H21: 109 | I21: 115 | J21: =I21/H21-1 -> 0.055045872 | K21: 93 | L21: 81 | M21: 110 | N21: =M21/L21-1 -> 0.35802469 | O21: =C21+G21+K21 -> 216 | P21: =D21+H21+L21 -> 195 | Q21: =E21+I21+M21 -> 239 | R21: =Q21/P21-1 -> 0.22564103
A22: Outros* | C22: 123 | D22: 122 | E22: 172 | F22: =E22/D22-1 -> 0.40983607 | G22: 193 | H22: 245 | I22: 244 | J22: =I22/H22-1 -> -0.0040816327 | K22: 27 | L22: 31 | M22: 29 | N22: =M22/L22-1 -> -0.064516129 | O22: =C22+G22+K22 -> 343 | P22: =D22+H22+L22 -> 398 | Q22: =E22+I22+M22 -> 445 | R22: =Q22/P22-1 -> 0.11809045
A23: Total | C23: =SUM(C15:C22)+C14+C9 -> 5741 | D23: =SUM(D15:D22)+D14+D9 -> 5045 | E23: =SUM(E15:E22)+E14+E9 -> 5259 | F23: =E23/D23-1 -> 0.042418236 | G23: =SUM(G15:G22)+G14+G9 -> 42084 | H23: =SUM(H15:H22)+H14+H9 -> 41184 | I23: =SUM(I15:I22)+I14+I9 -> 43307 | J23: =I23/H23-1 -> 0.051549145 | K23: =SUM(K15:K22)+K14+K9 -> 12947 | L23: =SUM(L15:L22)+L14+L9 -> 13471 | M23: =SUM(M15:M22)+M14+M9 -> 13692 | N23: =M23/L23-1 -> 0.016405612 | O23: =SUM(O15:O22)+O14+O9 -> 60772 | P23: =SUM(P15:P22)+P14+P9 -> 59700 | Q23: =SUM(Q15:Q22)+Q14+Q9 -> 62258 | R23: =Q23/P23-1 -> 0.042847571
A24: * Inclui veículos de tração animal, veículos sobre carris, máquinas industriais e não definidos

Sheet 2.2
A1: Quadro 2.2 Veículos intervenientes em acidentes com vítimas em Portugal por categoria e idade do veículo
A3: Categoria e idade do veículo | B3: ≤ 4 anos | E3: 5 a 9 anos | H3: 10 a 14 anos | K3: 15 a 19 anos | N3: 20 a 24 anos | Q3: ≥ 25 anos | T3: n.d. | W3: Total
B4: 2019 | C4: 2023 | D4: 2024 | E4: 2019 | F4: 2023 | G4: 2024 | H4: 2019 | I4: 2023 | J4: 2024 | K4: 2019 | L4: 2023 | M4: 2024 | N4: 2019 | O4: 2023 | P4: 2024 | Q4: 2019 | R4: 2023 | S4: 2024 | T4: 2019 | U4: 2023 | V4: 2024 | W4: 2019 | X4: 2023 | Y4: 2024
A5: Veículo ligeiro | B5: 7963 | C5: 5733 | D5: 6068 | E5: 7072 | F5: 8075 | G5: 8825 | H5: 9078 | I5: 6567 | J5: 6395 | K5: 9960 | L5: 7945 | M5: 7680 | N5: 7697 | O5: 8038 | P5: 7700 | Q5: 3408 | R5: 5927 | S5: 7043 | T5: 487 | U5: 256 | V5: 284 | W5: =T5+Q5+N5+K5+H5+E5+B5 -> 45665 | X5: =U5+R5+O5+L5+I5+F5+C5 -> 42541 | Y5: =V5+S5+P5+M5+J5+G5+D5 -> 43995
A6: Veículo pesado | B6: 325 | C6: 401 | D6: 447 | E6: 342 | F6: 348 | G6: 444 | H6: 423 | I6: 294 | J6: 306 | K6: 322 | L6: 297 | M6: 268 | N6: 169 | O6: 131 | P6: 165 | Q6: 74 | R6: 107 | S6: 114 | T6: 24 | U6: 14 | V6: 5 | W6: =T6+Q6+N6+K6+H6+E6+B6 -> 1679 | X6: =U6+R6+O6+L6+I6+F6+C6 -> 1592 | Y6: =V6+S6+P6+M6+J6+G6+D6 -> 1749
A7: Ciclomotor | B7: 464 | C7: 269 | D7: 235 | E7: 311 | F7: 288 | G7: 234 | H7: 669 | I7: 199 | J7: 125 | K7: 205 | L7: 284 | M7: 368 | N7: 281 | O7: 178 | P7: 125 | Q7: 559 | R7: 662 | S7: 578 | T7: 17 | U7: 5 | V7: 14 | W7: =T7+Q7+N7+K7+H7+E7+B7 -> 2506 | X7: =U7+R7+O7+L7+I7+F7+C7 -> 1885 | Y7: =V7+S7+P7+M7+J7+G7+D7 -> 1679
A8: Motociclo cilindrada <= 125cc | B8: 2057 | C8: 2307 | D8: 2625 | E8: 1211 | F8: 1548 | G8: 1538 | H8: 500 | I8: 834 | J8: 843 | K8: 229 | L8: 269 | M8: 318 | N8: 232 | O8: 185 | P8: 166 | Q8: 206 | R8: 362 | S8: 357 | T8: 16 | U8: 15 | V8: 31 | W8: =T8+Q8+N8+K8+H8+E8+B8 -> 4451 | X8: =U8+R8+O8+L8+I8+F8+C8 -> 5520 | Y8: =V8+S8+P8+M8+J8+G8+D8 -> 5878
A9: Motociclo cilindrada > 125cc | B9: 1007 | C9: 1360 | D9: 1510 | E9: 405 | F9: 691 | G9: 855 | H9: 483 | I9: 346 | J9: 318 | K9: 472 | L9: 531 | M9: 497 | N9: 420 | O9: 534 | P9: 464 | Q9: 285 | R9: 451 | S9: 569 | T9: 15 | U9: 9 | V9: 25 | W9: =T9+Q9+N9+K9+H9+E9+B9 -> 3087 | X9: =U9+R9+O9+L9+I9+F9+C9 -> 3922 | Y9: =V9+S9+P9+M9+J9+G9+D9 -> 4238
A10: Velocípede | B10: 207 | C10: 450 | D10: 487 | E10: 57 | F10: 45 | G10: 53 | H10: 11 | I10: 26 | J10: 14 | K10: 14 | L10: 3 | M10: 3 | N10: 3 | O10: 9 | P10: 18 | Q10: 5 | R10: 4 | S10: 6 | T10: 2134 | U10: 2792 | V10: 3120 | W10: =T10+Q10+N10+K10+H10+E10+B10 -> 2431 | X10: =U10+R10+O10+L10+I10+F10+C10 -> 3329 | Y10: =V10+S10+P10+M10+J10+G10+D10 -> 3701
A11: Quadriciclo | B11: 55 | C11: 49 | D11: 62 | E11: 54 | F11: 37 | G11: 46 | H11: 144 | I11: 48 | J11: 41 | K11: 76 | L11: 82 | M11: 87 | N11: 18 | O11: 42 | P11: 33 | Q11: 0 | R11: 18 | S11: 18 | T11: 0 | U11: 1 | V11: 4 | W11: =T11+Q11+N11+K11+H11+E11+B11 -> 347 | X11: =U11+R11+O11+L11+I11+F11+C11 -> 277 | Y11: =V11+S11+P11+M11+J11+G11+D11 -> 291
A12: Triciclo | B12: 22 | C12: 11 | D12: 18 | E12: 10 | F12: 13 | G12: 10 | H12: 8 | I12: 11 | J12: 7 | K12: 3 | L12: 2 | M12: 4 | N12: 2 | O12: 2 | P12: 2 | Q12: 1 | R12: 1 | S12: 2 | T12: 1 | U12: 1 | V12: 0 | W12: =T12+Q12+N12+K12+H12+E12+B12 -> 47 | X12: =U12+R12+O12+L12+I12+F12+C12 -> 41 | Y12: =V12+S12+P12+M12+J12+G12+D12 -> 43
A13: Veículo agrícola | B13: 55 | C13: 68 | D13: 53 | E13: 20 | F13: 23 | G13: 33 | H13: 20 | I13: 15 | J13: 20 | K13: 35 | L13: 20 | M13: 9 | N13: 22 | O13: 15 | P13: 19 | Q13: 60 | R13: 53 | S13: 82 | T13: 4 | U13: 1 | V13: 23 | W13: =T13+Q13+N13+K13+H13+E13+B13 -> 216 | X13: =U13+R13+O13+L13+I13+F13+C13 -> 195 | Y13: =V13+S13+P13+M13+J13+G13+D13 -> 239
A14: Outros* | B14: 48 | C14: 30 | D14: 15 | E14: 8 | F14: 6 | G14: 4 | H14: 2 | I14: 4 | J14: 8 | K14: 3 | L14: 4 | M14: 4 | N14: 3 | O14: 3 | P14: 1 | Q14: 2 | R14: 4 | S14: 1 | T14: 277 | U14: 347 | V14: 412 | W14: =T14+Q14+N14+K14+H14+E14+B14 -> 343 | X14: =U14+R14+O14+L14+I14+F14+C14 -> 398 | Y14: =V14+S14+P14+M14+J14+G14+D14 -> 445
A15: Total | B15: =SUM(B5:B14) -> 12203 | C15: =SUM(C5:C14) -> 10678 | D15: =SUM(D5:D14) -> 11520 | E15: =SUM(E5:E14) -> 9490 | F15: =SUM(F5:F14) -> 11074 | G15: =SUM(G5:G14) -> 12042 | H15: =SUM(H5:H14) -> 11338 | I15: =SUM(I5:I14) -> 8344 | ... Y15: =SUM(Y5:Y14) -> 62258
A16: * Inclui veículos de tração animal, veículos sobre carris, máquinas industriais e não definidos
A19: Categoria e idade do veículo | B19: ≤ 4 anos | E19: 5 a 9 anos | H19: 10 a 14 anos | K19: 15 a 19 anos | N19: 20 a 24 anos | Q19: > 25 anos | T19: n.d. | W19: Total
B20: ∆(%) 23/19 | C20: ∆(%) 24/19 | D20: ∆(%) 24/23 | E20: ∆(%) 23/19 | F20: ∆(%) 24/19 | G20: ∆(%) 24/23 | H20: ∆(%) 23/19 | I20: ∆(%) 24/19 | J20: ∆(%) 24/23 | K20: ∆(%) 23/19 | L20: ∆(%) 24/19 | M20: ∆(%) 24/23 | N20: ∆(%) 23/19 | O20: ∆(%) 24/19 | P20: ∆(%) 24/23 | Q20: ∆(%) 23/19 | R20: ∆(%) 24/19 | S20: ∆(%) 24/23 | T20: ∆(%) 23/19 | U20: ∆(%) 24/19 | V20: ∆(%) 24/23 | W20: ∆(%) 23/19 | X20: ∆(%) 24/19 | Y20: ∆(%) 24/23
A21: Veículo ligeiro | B21: =C5/B5-1 -> -0.28004521 | C21: =D5/B5-1 -> -0.23797564 | D21: =D5/C5-1 -> 0.05843363 | E21: =F5/E5-1 -> 0.14182692 | F21: =G5/E5-1 -> 0.24787896 | G21: =G5/F5-1 -> 0.092879257 | H21: =I5/H5-1 -> -0.27660278 | I21: =J5/H5-1 -> -0.29554968 | J21: =J5/I5-1 -> -0.026191564 | K21: =L5/K5-1 -> -0.20230924 | L21: =M5/K5-1 -> -0.22891566 | M21: =M5/L5-1 -> -0.033354311 | N21: =O5/N5-1 -> 0.044302975 | O21: =P5/N5-1 -> 0.00038976225 | P21: =P5/O5-1 -> -0.042050261 | Q21: =R5/Q5-1 -> 0.73914319 | R21: =S5/Q5-1 -> 1.066608 | S21: =S5/R5-1 -> 0.18829087 | T21: =U5/T5-1 -> -0.47433265 | U21: =V5/T5-1 -> -0.41683778 | V21: =V5/U5-1 -> 0.109375 | W21: =X5/W5-1 -> -0.068411256 | X21: =Y5/W5-1 -> -0.036570678 | Y21: =Y5/X5-1 -> 0.034178792
A22: Veículo pesado | B22: =C6/B6-1 -> 0.23384615 | C22: =D6/B6-1 -> 0.37538462 | D22: =D6/C6-1 -> 0.11471322 | E22: =F6/E6-1 -> 0.01754386 | F22: =G6/E6-1 -> 0.29824561 | G22: =G6/F6-1 -> 0.27586207 | H22: =I6/H6-1 -> -0.30496454 | I22: =J6/H6-1 -> -0.27659574 | J22: =J6/I6-1 -> 0.040816327 | K22: =L6/K6-1 -> -0.077639752 | L22: =M6/K6-1 -> -0.16770186 | M22: =M6/L6-1 -> -0.097643098 | N22: =O6/N6-1 -> -0.22485207 | O22: =P6/N6-1 -> -0.023668639 | P22: =P6/O6-1 -> 0.25954198 | Q22: =R6/Q6-1 -> 0.44594595 | R22: =S6/Q6-1 -> 0.54054054 | S22: =S6/R6-1 -> 0.065420561 | T22: =U6/T6-1 -> -0.41666667 | U22: =V6/T6-1 -> -0.79166667 | V22: =V6/U6-1 -> -0.64285714 | W22: =X6/W6-1 -> -0.051816557 | X22: =Y6/W6-1 -> 0.041691483 | Y22: =Y6/X6-1 -> 0.09861809
A23: Ciclomotor | B23: =C7/B7-1 -> -0.42025862 | C23: =D7/B7-1 -> -0.49353448 | D23: =D7/C7-1 -> -0.12639405 | E23: =F7/E7-1 -> -0.073954984 | F23: =G7/E7-1 -> -0.24758842 | G23: =G7/F7-1 -> -0.1875 | H23: =I7/H7-1 -> -0.70254111 | I23: =J7/H7-1 -> -0.81315396 | J23: =J7/I7-1 -> -0.3718593 | K23: =L7/K7-1 -> 0.38536585 | L23: =M7/K7-1 -> 0.79512195 | M23: =M7/L7-1 -> 0.29577465 | N23: =O7/N7-1 -> -0.36654804 | O23: =P7/N7-1 -> -0.55516014 | P23: =P7/O7-1 -> -0.29775281 | Q23: =R7/Q7-1 -> 0.1842576 | R23: =S7/Q7-1 -> 0.033989267 | S23: =S7/R7-1 -> -0.12688822 | T23: =U7/T7-1 -> -0.70588235 | U23: =V7/T7-1 -> -0.17647059 | V23: =V7/U7-1 -> 1.8 | W23: =X7/W7-1 -> -0.24780527 | X23: =Y7/W7-1 -> -0.33000798 | Y23: =Y7/X7-1 -> -0.10928382
A24: Motociclo cilindrada <= 125cc | B24: =C8/B8-1 -> 0.12153622 | C24: =D8/B8-1 -> 0.27613029 | D24: =D8/C8-1 -> 0.13784135 | E24: =F8/E8-1 -> 0.27828241 | F24: =G8/E8-1 -> 0.27002477 | G24: =G8/F8-1 -> -0.0064599483 | H24: =I8/H8-1 -> 0.668 | I24: =J8/H8-1 -> 0.686 | J24: =J8/I8-1 -> 0.010791367 | K24: =L8/K8-1 -> 0.17467249 | L24: =M8/K8-1 -> 0.38864629 | M24: =M8/L8-1 -> 0.18215613 | N24: =O8/N8-1 -> -0.20258621 | O24: =P8/N8-1 -> -0.28448276 | P24: =P8/O8-1 -> -0.1027027 | Q24: =R8/Q8-1 -> 0.75728155 | R24: =S8/Q8-1 -> 0.73300971 | S24: =S8/R8-1 -> -0.013812155 | T24: =U8/T8-1 -> -0.0625 | U24: =V8/T8-1 -> 0.9375 | V24: =V8/U8-1 -> 1.0666667 | W24: =X8/W8-1 -> 0.24017075 | X24: =Y8/W8-1 -> 0.32060211 | Y24: =Y8/X8-1 -> 0.064855072
A25: Motociclo cilindrada > 125cc | B25: =C9/B9-1 -> 0.35054618 | C25: =D9/B9-1 -> 0.49950348 | D25: =D9/C9-1 -> 0.11029412 | E25: =F9/E9-1 -> 0.70617284 | F25: =G9/E9-1 -> 1.1111111 | G25: =G9/F9-1 -> 0.23733719 | H25: =I9/H9-1 -> -0.28364389 | I25: =J9/H9-1 -> -0.34161491 | J25: =J9/I9-1 -> -0.080924855 | K25: =L9/K9-1 -> 0.125 | L25: =M9/K9-1 -> 0.052966102 | M25: =M9/L9-1 -> -0.064030132 | N25: =O9/N9-1 -> 0.27142857 | O25: =P9/N9-1 -> 0.1047619 | P25: =P9/O9-1 -> -0.13108614 | Q25: =R9/Q9-1 -> 0.58245614 | R25: =S9/Q9-1 -> 0.99649123 | S25: =S9/R9-1 -> 0.2616408 | T25: =U9/T9-1 -> -0.4 | U25: =V9/T9-1 -> 0.66666667 | V25: =V9/U9-1 -> 1.7777778 | W25: =X9/W9-1 -> 0.27048915 | X25: =Y9/W9-1 -> 0.3728539 | Y25: =Y9/X9-1 -> 0.080571137
A26: Velocípede | B26: =C10/B10-1 -> 1.173913 | C26: =D10/B10-1 -> 1.352657 | D26: =D10/C10-1 -> 0.082222222 | E26: =F10/E10-1 -> -0.21052632 | F26: =G10/E10-1 -> -0.070175439 | G26: =G10/F10-1 -> 0.17777778 | H26: =I10/H10-1 -> 1.3636364 | I26: =J10/H10-1 -> 0.27272727 | J26: =J10/I10-1 -> -0.46153846 | K26: =L10/K10-1 -> -0.78571429 | L26: =M10/K10-1 -> -0.78571429 | M26: =M10/L10-1 -> 0 | N26: =O10/N10-1 -> 2 | O26: =P10/N10-1 -> 5 | P26: =P10/O10-1 -> 1 | Q26: =R10/Q10-1 -> -0.2 | R26: =S10/Q10-1 -> 0.2 | S26: =S10/R10-1 -> 0.5 | T26: =U10/T10-1 -> 0.30834114 | U26: =V10/T10-1 -> 0.46204311 | V26: =V10/U10-1 -> 0.11747851 | W26: =X10/W10-1 -> 0.36939531 | X26: =Y10/W10-1 -> 0.52241876 | Y26: =Y10/X10-1 -> 0.11174527
A27: Quadriciclo | B27: =C11/B11-1 -> -0.10909091 | C27: =D11/B11-1 -> 0.12727273 | D27: =D11/C11-1 -> 0.26530612 | E27: =F11/E11-1 -> -0.31481481 | F27: =G11/E11-1 -> -0.14814815 | G27: =G11/F11-1 -> 0.24324324 | H27: =I11/H11-1 -> -0.66666667 | I27: =J11/H11-1 -> -0.71527778 | J27: =J11/I11-1 -> -0.14583333 | K27: =L11/K11-1 -> 0.078947368 | L27: =M11/K11-1 -> 0.14473684 | M27: =M11/L11-1 -> 0.06097561 | N27: =O11/N11-1 -> 1.3333333 | O27: =P11/N11-1 -> 0.83333333 | P27: =P11/O11-1 -> -0.21428571 | Q27: - | R27: - | S27: =S11/R11-1 -> 0 | T27: - | U27: - | V27: =V11/U11-1 -> 3 | W27: =X11/W11-1 -> -0.20172911 | X27: =Y11/W11-1 -> -0.16138329 | Y27: =Y11/X11-1 -> 0.050541516
A28: Triciclo | B28: =C12/B12-1 -> -0.5 | C28: =D12/B12-1 -> -0.18181818 | D28: =D12/C12-1 -> 0.63636364 | E28: =F12/E12-1 -> 0.3 | F28: =G12/E12-1 -> 0 | G28: =G12/F12-1 -> -0.23076923 | H28: =I12/H12-1 -> 0.375 | I28: =J12/H12-1 -> -0.125 | J28: =J12/I12-1 -> -0.36363636 | K28: =L12/K12-1 -> -0.33333333 | L28: =M12/K12-1 -> 0.33333333 | M28: =M12/L12-1 -> 1 | N28: =O12/N12-1 -> 0 | O28: =P12/N12-1 -> 0 | P28: - | Q28: =R12/Q12-1 -> 0 | R28: =S12/Q12-1 -> 1 | S28: =S12/R12-1 -> 1 | T28: =U12/T12-1 -> 0 | U28: =V12/T12-1 -> -1 | V28: - | W28: =X12/W12-1 -> -0.12765957 | X28: =Y12/W12-1 -> -0.085106383 | Y28: =Y12/X12-1 -> 0.048780488
A29: Veículo agrícola | B29: =C13/B13-1 -> 0.23636364 | C29: =D13/B13-1 -> -0.036363636 | D29: =D13/C13-1 -> -0.22058824 | E29: =F13/E13-1 -> 0.15 | F29: =G13/E13-1 -> 0.65 | G29: =G13/F13-1 -> 0.43478261 | H29: =I13/H13-1 -> -0.25 | I29: =J13/H13-1 -> 0 | J29: =J13/I13-1 -> 0.33333333 | K29: =L13/K13-1 -> -0.42857143 | L29: =M13/K13-1 -> -0.74285714 | M29: =M13/L13-1 -> -0.55 | N29: =O13/N13-1 -> -0.31818182 | O29: =P13/N13-1 -> -0.13636364 | P29: =P13/O13-1 -> 0.26666667 | Q29: =R13/Q13-1 -> -0.11666667 | R29: =S13/Q13-1 -> 0.36666667 | S29: =S13/R13-1 -> 0.54716981 | T29: =U13/T13-1 -> -0.75 | U29: =V13/T13-1 -> 4.75 | V29: =V13/U13-1 -> 22 | W29: =X13/W13-1 -> -0.097222222 | X29: =Y13/W13-1 -> 0.10648148 | Y29: =Y13/X13-1 -> 0.22564103
A30: Outros* | B30: =C14/B14-1 -> -0.375 | C30: =D14/B14-1 -> -0.6875 | D30: =D14/C14-1 -> -0.5 | E30: =F14/E14-1 -> -0.25 | F30: =G14/E14-1 -> -0.5 | G30: =G14/F14-1 -> -0.33333333 | H30: =I14/H14-1 -> 1 | I30: =J14/H14-1 -> 3 | J30: =J14/I14-1 -> 1 | K30: =L14/K14-1 -> 0.33333333 | L30: =M14/K14-1 -> 0.33333333 | M30: =M14/L14-1 -> 0 | N30: =O14/N14-1 -> 0 | O30: =P14/N14-1 -> -0.66666667 | P30: =P14/O14-1 -> -0.66666667 | Q30: =R14/Q14-1 -> 1 | R30: =S14/Q14-1 -> -0.5 | S30: =S14/R14-1 -> -0.75 | T30: =U14/T14-1 -> 0.25270758 | U30: =V14/T14-1 -> 0.48736462 | V30: =V14/U14-1 -> 0.18731988 | W30: =X14/W14-1 -> 0.16034985 | X30: =Y14/W14-1 -> 0.29737609 | Y30: =Y14/X14-1 -> 0.11809045
A31: Total | B31: =C15/B15-1 -> -0.12496927 | C31: =D15/B15-1 -> -0.055969843 | D31: =D15/C15-1 -> 0.078853718 | E31: =F15/E15-1 -> 0.16691254 | F31: =G15/E15-1 -> 0.26891465 | G31: =G15/F15-1 -> 0.087411956 | H31: =I15/H15-1 -> -0.26406774 | I31: =J15/H15-1 -> -0.28761686 | J31: =J15/I15-1 -> -0.031999041 | K31: =L15/K15-1 -> -0.16626911 | L31: =M15/K15-1 -> -0.18385016 | M31: =M15/L15-1 -> -0.02108721 | N31: =O15/N15-1 -> 0.032779473 | O31: =P15/N15-1 -> -0.017407031 | P31: =P15/O15-1 -> -0.04859363 | Q31: =R15/Q15-1 -> 0.64978261 | R31: =S15/Q15-1 -> 0.90652174 | S31: =S15/R15-1 -> 0.15561998 | T31: =U15/T15-1 -> 0.15663866 | U31: =V15/T15-1 -> 0.31697479 | V31: =V15/U15-1 -> 0.13862249 | W31: =X15/W15-1 -> -0.017639702 | X31: =Y15/W15-1 -> 0.02445205 | Y31: =Y15/X15-1 -> 0.042847571
A32: * Inclui veículos de tração animal, veículos sobre carris, máquinas industriais e não definidos

Sheet 2.3
A1: Quadro 2.3 Veículos intervenientes em acidentes com vítimas em Portugal por NUTS I e categoria de veículo
A4: NUTS I e categoria de veículo | B4: Veículos intervenientes
B5: 2019 | C5: 2023 | D5: 2024 | E5: 2024 (%) | F5: ∆(%) 24/23 | G5: ∆(%) 24/19
A6: Continente | B6: =SUM(B7:B16) -> 58300 | C6: =SUM(C7:C16) -> 57041 | D6: =SUM(D7:D16) -> 59494 | E6: =D6/$D$6 -> 1 | F6: =D6/C6-1 -> 0.043004155 | G6: =D6/B6-1 -> 0.020480274
A7: Veículo ligeiro | B7: 43934 | C7: 40663 | D7: 42106 | E7: =D7/$D$6 -> 0.70773523 | F7: =D7/C7-1 -> 0.035486806 | G7: =D7/B7-1 -> -0.041607866
A8: Veículo pesado | B8: 1620 | C8: 1533 | D8: 1673 | E8: =D8/$D$6 -> 0.028120483 | F8: =D8/C8-1 -> 0.091324201 | G8: =D8/B8-1 -> 0.032716049
A9: Ciclomotor | B9: 2378 | C9: 1784 | D9: 1587 | E9: =D9/$D$6 -> 0.026674959 | F9: =D9/C9-1 -> -0.11042601 | G9: =D9/B9-1 -> -0.33263246
A10: Motociclo cilindrada <= 125cc | B10: 4155 | C10: 5199 | D10: 5508 | E10: =D10/$D$6 -> 0.092580764 | F10: =D10/C10-1 -> 0.059434507 | G10: =D10/B10-1 -> 0.32563177
A11: Motociclo cilindrada > 125cc | B11: 2946 | C11: 3737 | D11: 4038 | E11: =D11/$D$6 -> 0.06787239 | F11: =D11/C11-1 -> 0.080545892 | G11: =D11/B11-1 -> 0.3706721
A12: Velocípede | B12: 2344 | C12: 3239 | D12: 3602 | E12: =D12/$D$6 -> 0.06054392 | F12: =D12/C12-1 -> 0.11207163 | G12: =D12/B12-1 -> 0.53668942
A13: Quadriciclo | B13: 326 | C13: 262 | D13: 275 | E13: =D13/$D$6 -> 0.0046223149 | F13: =D13/C13-1 -> 0.049618321 | G13: =D13/B13-1 -> -0.15644172
A14: Triciclo | B14: 47 | C14: 40 | D14: 37 | E14: =D14/$D$6 -> 0.00062191145 | F14: =D14/C14-1 -> -0.075 | G14: =D14/B14-1 -> -0.21276596
A15: Veículo agrícola | B15: 212 | C15: 189 | D15: 228 | E15: =D15/$D$6 -> 0.0038323192 | F15: =D15/C15-1 -> 0.20634921 | G15: =D15/B15-1 -> 0.075471698
A16: Outros* | B16: 338 | C16: 395 | D16: 440 | E16: =D16/$D$6 -> 0.0073957038 | F16: =D16/C16-1 -> 0.11392405 | G16: =D16/B16-1 -> 0.30177515
A17: R.A. Açores | B17: =SUM(B18:B27) -> 961 | C17: =SUM(C18:C27) -> 1013 | D17: =SUM(D18:D27) -> 1083 | E17: =D17/$D$17 -> 1 | F17: =D17/C17-1 -> 0.069101678 | G17: =D17/B17-1 -> 0.12695109
A18: Veículo ligeiro | B18: 719 | C18: 776 | D18: 811 | E18: =D18/$D$17 -> 0.7488458 | F18: =D18/C18-1 -> 0.045103093 | G18: =D18/B18-1 -> 0.12795549
A19: Veículo pesado | B19: 15 | C19: 15 | D19: 21 | E19: =D19/$D$17 -> 0.019390582 | F19: =D19/C19-1 -> 0.4 | G19: =D19/B19-1 -> 0.4
A20: Ciclomotor | B20: 78 | C20: 63 | D20: 62 | E20: =D20/$D$17 -> 0.057248384 | F20: =D20/C20-1 -> -0.015873016 | G20: =D20/B20-1 -> -0.20512821
A21: Motociclo cilindrada <= 125cc | B21: 56 | C21: 45 | D21: 73 | E21: =D21/$D$17 -> 0.067405355 | F21: =D21/C21-1 -> 0.62222222 | G21: =D21/B21-1 -> 0.30357143
A22: Motociclo cilindrada > 125cc | B22: 32 | C22: 48 | D22: 41 | E22: =D22/$D$17 -> 0.037857802 | F22: =D22/C22-1 -> -0.14583333 | G22: =D22/B22-1 -> 0.28125
A23: Velocípede | B23: 44 | C23: 48 | D23: 44 | E23: =D23/$D$17 -> 0.040627886 | F23: =D23/C23-1 -> -0.083333333 | G23: =D23/B23-1 -> 0
A24: Quadriciclo | B24: 11 | C24: 11 | D24: 14 | E24: =D24/$D$17 -> 0.012927054 | F24: =D24/C24-1 -> 0.27272727 | G24: =D24/B24-1 -> 0.27272727
A25: Triciclo | B25: 0 | C25: 0 | D25: 2 | E25: =D25/$D$17 -> 0.0018467221 | F25: - | G25: -
A26: Veículo agrícola | B26: 4 | C26: 5 | D26: 11 | E26: =D26/$D$17 -> 0.010156971 | F26: =D26/C26-1 -> 1.2 | G26: =D26/B26-1 -> 1.75
A27: Outros* | B27: 2 | C27: 2 | D27: 4 | E27: =D27/$D$17 -> 0.0036934441 | F27: =D27/C27-1 -> 1 | G27: =D27/B27-1 -> 1
A28: R.A. Madeira | B28: =SUM(B29:B38) -> 1511 | C28: =SUM(C29:C38) -> 1646 | D28: =SUM(D29:D38) -> 1681 | E28: =D28/$D$28 -> 1 | F28: =D28/C28-1 -> 0.02126367 | G28: =D28/B28-1 -> 0.11250827
A29: Veículo ligeiro | B29: 1012 | C29: 1102 | D29: 1078 | E29: =D29/$D$28 -> 0.64128495 | F29: =D29/C29-1 -> -0.021778584 | G29: =D29/B29-1 -> 0.065217391
A30: Veículo pesado | B30: 44 | C30: 44 | D30: 55 | E30: =D30/$D$28 -> 0.03271862 | F30: =D30/C30-1 -> 0.25 | G30: =D30/B30-1 -> 0.25
A31: Ciclomotor | B31: 50 | C31: 38 | D31: 30 | E31: =D31/$D$28 -> 0.01784652 | F31: =D31/C31-1 -> -0.21052632 | G31: =D31/B31-1 -> -0.4
A32: Motociclo cilindrada <= 125cc | B32: 240 | C32: 276 | D32: 297 | E32: =D32/$D$28 -> 0.17668055 | F32: =D32/C32-1 -> 0.076086957 | G32: =D32/B32-1 -> 0.2375
A33: Motociclo cilindrada > 125cc | B33: 109 | C33: 137 | D33: 159 | E33: =D33/$D$28 -> 0.094586556 | F33: =D33/C33-1 -> 0.16058394 | G33: =D33/B33-1 -> 0.4587156
A34: Velocípede | B34: 43 | C34: 42 | D34: 55 | E34: =D34/$D$28 -> 0.03271862 | F34: =D34/C34-1 -> 0.30952381 | G34: =D34/B34-1 -> 0.27906977
A35: Quadriciclo | B35: 10 | C35: 4 | D35: 2 | E35: =D35/$D$28 -> 0.001189768 | F35: =D35/C35-1 -> -0.5 | G35: =D35/B35-1 -> -0.8
A36: Triciclo | B36: 0 | C36: 1 | D36: 4 | E36: =D36/$D$28 -> 0.002379536 | F36: =D36/C36-1 -> 3 | G36: -
A37: Veículo agrícola | B37: 0 | C37: 1 | D37: 0 | E37: =D37/$D$28 -> 0 | F37: =D37/C37-1 -> -1 | G37: -
A38: Outros* | B38: 3 | C38: 1 | D38: 1 | E38: =D38/$D$28 -> 0.000594884 | F38: =D38/C38-1 -> 0 | G38: =D38/B38-1 -> -0.66666667
A39: Portugal | B39: =B28+B17+B6 -> 60772 | C39: =C28+C17+C6 -> 59700 | D39: =D28+D17+D6 -> 62258 | E39: - | F39: =D39/C39-1 -> 0.042847571 | G39: =D39/B39-1 -> 0.02445205
